Workbook

Sheet Budget
C1: iCACCESS 2026: Budget
C2: No of accepted Papers | D2: 97
C3: No of Registration | D3: =D2*0.9 -> 87.3
C4: No of Guests (Internal + External) | D4: 30
C5: No of Organizers (Faculty and Officer) | D5: 40
C6: No of Session Chairs | D6: =2*D3/6 -> 29.1
C7: No of Volenteers | D7: 20
C8: Media | D8: 10
C9: Dollar rate (USD to BDT) | D9: 124
C11: Expenditure | H11: Revenue
B12: Responsible | C12: Item | D12: Price per Unit | E12: No of Units | F12: Cost | H12: Item | I12: Amount
B13: Nafees Mansoor, Rokon | C13: IEEE Registration | D13: =1450*D9 -> 179800 | E13: 1 | F13: =D13*E13 -> 179800 | H13: Savings | I13: 0
B14: Nafees Mansoor, Rokon | C14: Per Paper Registration | D14: =22*D9 -> 2728 | E14: =D3 -> 87.3 | F14: =D14*E14 -> 238154.4 | H14: Regsitration (Local) | I14: =8000*D3*0.95 -> 663480
B15: Dean, SSE | C15: Bag | D15: 780 | E15: 225 | F15: =D15*E15 -> 175500 | H15: Regsitration (International) | I15: =180*D9*D3*0.05 -> 97426.8
B16: Dean, SSE | C16: Pendrive | D16: 400 | E16: 100 | F16: =D16*E16 -> 40000 | H16: Sponsor (US-DK) | I16: 50000
B17: Dean, SSE | C17: Pen and Pad | D17: 60 | E17: 150 | F17: =D17*E17 -> 9000 | H17: ULAB | I17: 100000
B18: Nazmul, Zafor, Trina | C18: Dinner | D18: 550 | E18: =0.8*(D3+D4+D5+D6+D7+20) -> 181.12 | F18: =D18*E18 -> 99616 | H18: Others (Banks) | I18: 0
B19: Dean, SSE | C19: Crest | D19: 450 | E19: =D6+0.5*D5 -> 49.1 | F19: =D19*E19 -> 22095
B20: Dean, SSE | C20: Special Crest | D20: 1400 | E20: 10 | F20: =D20*E20 -> 14000
B21: Dean, SSE | C21: ID | D21: 90 | E21: 130 | F21: =D21*E21 -> 11700
B22: Nazmul, Zafor, Trina | C22: Snacks | F22: 20000
B23: Nazmul, Zafor, Trina | C23: Lunch | D23: 200 | E23: =D3+D4+D5+D6+D7+20 -> 226.4 | F23: =D23*E23 -> 45280
B24: Dean, SSE | C24: Branding | F24: 20000
B25: Dean, SSE | C25: Printing (Banner) | F25: 30000
C26: Cultural | F26: 5000
B27: Dean, SSE, Nazmul | C27: Others (Coupons) | F27: 5000
F28: =SUM(F13:F27) -> 915145.4 | I28: =SUM(I13:I27) -> 910906.8
B29: Dean, SSE | C29: Opening ceremony
B30: Shihavuddin, Nafees Mansoor | C30: Session design and execution | H30: Surplus | I30: =I28-F28 -> -4238.6
B31: Dean, SSE | C31: General Invitation
B32: Dean, SSE | C32: Chief guest selection and invitation
B33: Dean, SSE | C33: Closing ceremony

Sheet Sessions
A1: Track | B1: Session ID | C1: Session Title | D1: Session Room
A2: Track 1: Computing and Intelligent Systems | B2: T1P1 | C2: Machine Learning Foundations and Intelligent Systems | D2: PD101
A3: Track 1: Computing and Intelligent Systems | B3: T1P2 | C3: Natural Language, Computer Vision, and Multimodal AI | D3: PD102
A4: Track 2: Wireless and Optical Communication | B4: T1P3 | C4: Wireless Networks and Optical Communication Systems | D4: PD103
A5: Track 1 & Track 5: Computing and Intelligent Systems | B5: T2P1 | C5: Cloud, Big Data, and Distributed Computing | D5: PD104
A7: Track 1: Computing and Intelligent Systems | B7: T2P2 | C7: Applied AI and Intelligent Computing Applications | D7: PD101
A9: Track 5: Digital Learning and Educational Technologies | B9: T2P3 | C9: AI-Enabled Digital Learning and Educational Technologies | D9: PD102
A10: Track 4: Smart and Cyber-Physical Systems | B10: T2P4 | C10: IoT, Embedded, and Cyber-Physical Systems | D10: PD103
A12: Track 1: Computing and Intelligent Systems | B12: T4P1 | C12: Machine Learning Applications and Data-Driven Systems | D12: https://bdren.zoom.us/j/8428351030?pwd=7kfJZ1PoRiAzd0aKSn3l28Yuta2D1P.1&omn=92475321723
A13: Track 2: Wireless and Optical Communication + Track 1: Computing and Intelligent Systems | B13: T4P2 | C13: Intelligent Communication Networks and Computing | D13: https://bdren.zoom.us/j/3426823862?pwd=qdTx7T0wafu1iseMaIbFJzZkwB20Gq.1&omn=9670458221
A14: Track 3: Electronics, Devices, and Nanotechnology + Track 1: Computing and Intelligent Systems | B14: T4P3 | C14: Electronics and Hardware for Intelligent Computing | D14: https://bdren.zoom.us/j/5012406330?pwd=czJaVXJnaHdJZlhpM21RWWF1a2hNQT09&omn=91831440282
A15: Track 1: Computing and Intelligent Systems | B15: T4P4 | C15: Cybersecurity, Blockchain, and Trustworthy Computing | D15: https://bdren.zoom.us/j/4074534482?pwd=krdtcqcqU2E4TPlssbKu9CBmk1aJre.1&omn=98496255250
... A17: Track 1: Computing and Intelligent Systems | B17: T4P6 | C17: Emerging Topics in Computing and Intelligent Systems | D17: https://meet.google.com/warndfcavc

Sheet Schedule
A1: iCACCESS 2026 (2-3 October)
A2: Schedule
A4: Day 1
A5: Time | B5: Event | C5: Venue
A6: 8:00-9:00 | B6: Registration
A7: 9:30-10:30 | B7: Opening Ceremony
A8: 10:40-11:40 | B8: Keynote Session 1
A9: 11:40-12:40 | B9: IEEE workshop - Responsible AI for Academic Research
A10: 11:40-12:40 | B10: Technical Session 1 (T1P1, T1P2, T1P3) | D10: 4x3=12
A11: 12:40-14:30 | B11: Prayer and Lunch Break
A12: 14:30-16:30 | B12: Technical Session 2 (T2P1, T2P2, T2P3, T2P4) | D12: 8x5=40
A13: 16:30-17:30 | B13: Keynote Session 2
A14: 18:30-20:30 | B14: Cultural Ceremony and Dinner
A16: Day 2
A17: Time | B17: Event | C17: Venue
A18: 11:00-13:00 | B18: Technical Session 4 (T4P1, T4P2, T4P3, T4P4, T4P5, T4P6) | C18: Online | D18: 8x6=48
A19: 14:30-15:30 | B19: Keynote Session 3 | C19: Online
A20: 18:00-19:00 | B20: Closing and Award Ceremony | C20: Online
D21: 140

Sheet Senior Faculty
A1: Name | B1: Designation | C1: Email | D1: Mobile | E1: Session 1 | F1: Assigned | G1: Session 2 | H1: Assigned | J1: Helper: Name | K1: Helper: Session Code | L1: Helper: Email | M1: Helper: Mobile | N1: Helper: Order
A2: Prof. Dr. Muhammad Golam Kibria | B2: Professor & Dean, SSE | C2: golam.kibria@ulab.edu.bd | D2: 01771122144 | E2: Keynote 2 | F2: =IF(TRIM(E2)="","No","Yes") -> Yes | H2: =IF(TRIM(G2)="","No","Yes") -> No | J2: =IF($A2="","",$A2) -> Prof. Dr. Muhammad Golam Kibria | K2: =$E2 -> Keynote 2 | L2: =IF($A2="","",$C2) -> golam.kibria@ulab.edu.bd | M2: =IF($A2="","",$D2) -> 01771122144 | N2: =IF($K2="","",COUNTIFS($K$2:$K2,$K2)) -> 1
A3: Prof. Dr. Nafees Mansoor | B3: Professor, CSE | C3: nafees.mansoor@ulab.edu.bd | D3: 01879242323 | E3: IEEE Workshop | F3: =IF(TRIM(E3)="","No","Yes") -> Yes | H3: =IF(TRIM(G3)="","No","Yes") -> No | J3: =IF($A3="","",$A3) -> Prof. Dr. Nafees Mansoor | K3: =$E3 -> IEEE Workshop | L3: =IF($A3="","",$C3) -> nafees.mansoor@ulab.edu.bd | M3: =IF($A3="","",$D3) -> 01879242323 | N3: =IF($K3="","",COUNTIFS($K$2:$K3,$K3)) -> 1
A4: Anwarul Haque Joarder | B4: Professor, CSE | C4: anwar.joarder@ulab.edu.bd | D4: 01977000805 | F4: =IF(TRIM(E4)="","No","Yes") -> No | H4: =IF(TRIM(G4)="","No","Yes") -> No | J4: =IF($A4="","",$A4) -> Anwarul Haque Joarder | K4: =$E4 | L4: =IF($A4="","",$C4) -> anwar.joarder@ulab.edu.bd | M4: =IF($A4="","",$D4) -> 01977000805 | N4: =IF($K4="","",COUNTIFS($K$2:$K4,$K4))
A5: Dr. T. M Abul Kalam Azad | B5: Associate Professor, CSE | C5: abul.kalam@ulab.edu.bd | D5: 01789379752 | E5: Keynote 1 | F5: =IF(TRIM(E5)="","No","Yes") -> Yes | H5: =IF(TRIM(G5)="","No","Yes") -> No | J5: =IF($A5="","",$A5) -> Dr. T. M Abul Kalam Azad | K5: =$E5 -> Keynote 1 | L5: =IF($A5="","",$C5) -> abul.kalam@ulab.edu.bd | M5: =IF($A5="","",$D5) -> 01789379752 | N5: =IF($K5="","",COUNTIFS($K$2:$K5,$K5)) -> 1
A6: Dr. Rezwan Al Islam Khan | B6: Associate Professor, CSE | C6: rezwan.islam@ulab.edu.bd | D6: 01712530199 | E6: T2P1 | F6: =IF(TRIM(E6)="","No","Yes") -> Yes | H6: =IF(TRIM(G6)="","No","Yes") -> No | J6: =IF($A6="","",$A6) -> Dr. Rezwan Al Islam Khan | K6: =$E6 -> T2P1 | L6: =IF($A6="","",$C6) -> rezwan.islam@ulab.edu.bd | M6: =IF($A6="","",$D6) -> 01712530199 | N6: =IF($K6="","",COUNTIFS($K$2:$K6,$K6)) -> 1
A7: Dr. Ayesha Akter Lata | B7: Assistant Professor, CSE | C7: ayesha.akter@ulab.edu.bd | D7: 01856412501 | E7: T1P1 | F7: =IF(TRIM(E7)="","No","Yes") -> Yes | G7: T4P3 | H7: =IF(TRIM(G7)="","No","Yes") -> Yes | J7: =IF($A7="","",$A7) -> Dr. Ayesha Akter Lata | K7: =$E7 -> T1P1 | L7: =IF($A7="","",$C7) -> ayesha.akter@ulab.edu.bd | M7: =IF($A7="","",$D7) -> 01856412501 | N7: =IF($K7="","",COUNTIFS($K$2:$K7,$K7)) -> 1
A8: Dr. Al Amin Sheikh | B8: Assistant Professor, CSE | C8: taskia.khatun@ulab.edu.bd | D8: 01701564663 | E8: T1P2 | F8: =IF(TRIM(E8)="","No","Yes") -> Yes | G8: T3P3 | H8: =IF(TRIM(G8)="","No","Yes") -> Yes | J8: =IF($A8="","",$A8) -> Dr. Al Amin Sheikh | K8: =$E8 -> T1P2 | L8: =IF($A8="","",$C8) -> taskia.khatun@ulab.edu.bd | M8: =IF($A8="","",$D8) -> 01701564663 | N8: =IF($K8="","",COUNTIFS($K$2:$K8,$K8)) -> 1
A9: Dr. Mst. Taskia Khatun | B9: Assistant Professor, CSE | C9: alamin.sheikh@ulab.edu.bd | D9: 01764912222 | E9: T2P2 | F9: =IF(TRIM(E9)="","No","Yes") -> Yes | H9: =IF(TRIM(G9)="","No","Yes") -> No | J9: =IF($A9="","",$A9) -> Dr. Mst. Taskia Khatun | K9: =$E9 -> T2P2 | L9: =IF($A9="","",$C9) -> alamin.sheikh@ulab.edu.bd | M9: =IF($A9="","",$D9) -> 01764912222 | N9: =IF($K9="","",COUNTIFS($K$2:$K9,$K9)) -> 1
A10: Dr. Nafiz Jaidye | B10: Assistant Professor, CSE | C10: nafiz.jaidye@ulab.edu.bd | D10: 01889121516 | E10: T2P3 | F10: =IF(TRIM(E10)="","No","Yes") -> Yes | G10: T3P5 | H10: =IF(TRIM(G10)="","No","Yes") -> Yes | J10: =IF($A10="","",$A10) -> Dr. Nafiz Jaidye | K10: =$E10 -> T2P3 | L10: =IF($A10="","",$C10) -> nafiz.jaidye@ulab.edu.bd | M10: =IF($A10="","",$D10) -> 01889121516 | N10: =IF($K10="","",COUNTIFS($K$2:$K10,$K10)) -> 1
A11: Raihan Kibria | B11: Senior Lecturer, CSE | C11: raihan.kibria@ulab.edu.bd | D11: 01819417956 | E11: T2P4 | F11: =IF(TRIM(E11)="","No","Yes") -> Yes | G11: T4P4 | H11: =IF(TRIM(G11)="","No","Yes") -> Yes | J11: =IF($A11="","",$A11) -> Raihan Kibria | K11: =$E11 -> T2P4 | L11: =IF($A11="","",$C11) -> raihan.kibria@ulab.edu.bd | M11: =IF($A11="","",$D11) -> 01819417956 | N11: =IF($K11="","",COUNTIFS($K$2:$K11,$K11)) -> 1
A12: Rubaiya Hafiz | B12: Senior Lecturer, CSE | C12: rubaiya.hafiz@ulab.edu.bd | D12: 01914194973 | E12: T3P1 | F12: =IF(TRIM(E12)="","No","Yes") -> Yes | H12: =IF(TRIM(G12)="","No","Yes") -> No | J12: =IF($A12="","",$A12) -> Rubaiya Hafiz | K12: =$E12 -> T3P1 | L12: =IF($A12="","",$C12) -> rubaiya.hafiz@ulab.edu.bd | M12: =IF($A12="","",$D12) -> 01914194973 | N12: =IF($K12="","",COUNTIFS($K$2:$K12,$K12)) -> 1
A13: Jannatul Ferdous Ruma | B13: Senior Lecturer, Course Coordinator, CSE | C13: jannatul.ferdous1@ulab.edu.bd | D13: 01710954167 | E13: T4P6 | F13: =IF(TRIM(E13)="","No","Yes") -> Yes | G13: T4P1 | H13: =IF(TRIM(G13)="","No","Yes") -> Yes | J13: =IF($A13="","",$A13) -> Jannatul Ferdous Ruma | K13: =$E13 -> T4P6 | L13: =IF($A13="","",$C13) -> jannatul.ferdous1@ulab.edu.bd | M13: =IF($A13="","",$D13) -> 01710954167 | N13: =IF($K13="","",COUNTIFS($K$2:$K13,$K13)) -> 1
A14: Dr. A.S.M. Shihavuddin | B14: Professor & HoD, EEE | C14: shihav.uddin@ulab.edu.bd | D14: 01847246426 | F14: =IF(TRIM(E14)="","No","Yes") -> No | H14: =IF(TRIM(G14)="","No","Yes") -> No | J14: =IF($A14="","",$A14) -> Dr. A.S.M. Shihavuddin | K14: =$E14 | L14: =IF($A14="","",$C14) -> shihav.uddin@ulab.edu.bd | M14: =IF($A14="","",$D14) -> 01847246426 | N14: =IF($K14="","",COUNTIFS($K$2:$K14,$K14))
A15: Ifat Al Baqee, PhD | B15: Associate Professor, EEE | C15: ifat.albaqee@ulab.edu.bd | D15: 01715135140 | E15: T4P2 | F15: =IF(TRIM(E15)="","No","Yes") -> Yes | H15: =IF(TRIM(G15)="","No","Yes") -> No | J15: =IF($A15="","",$A15) -> Ifat Al Baqee, PhD | K15: =$E15 -> T4P2 | L15: =IF($A15="","",$C15) -> ifat.albaqee@ulab.edu.bd | M15: =IF($A15="","",$D15) -> 01715135140 | N15: =IF($K15="","",COUNTIFS($K$2:$K15,$K15)) -> 1
A16: Md. Ashraful Haque, PhD | B16: Associate Professor, EEE | C16: ashraful.haque1@ulab.edu.bd | D16: 01745323543 | E16: T1P3 | F16: =IF(TRIM(E16)="","No","Yes") -> Yes | H16: =IF(TRIM(G16)="","No","Yes") -> No | J16: =IF($A16="","",$A16) -> Md. Ashraful Haque, PhD | K16: =$E16 -> T1P3 | L16: =IF($A16="","",$C16) -> ashraful.haque1@ulab.edu.bd | M16: =IF($A16="","",$D16) -> 01745323543 | N16: =IF($K16="","",COUNTIFS($K$2:$K16,$K16)) -> 1
A17: Mainul Haque | B17: Senior Lecturer, EEE | C17: mainul.haque@ulab.edu.bd | D17: 01717172837 | F17: =IF(TRIM(E17)="","No","Yes") -> No | G17: T4P5 | H17: =IF(TRIM(G17)="","No","Yes") -> Yes | J17: =IF($A17="","",$A17) -> Mainul Haque | K17: =$E17 | L17: =IF($A17="","",$C17) -> mainul.haque@ulab.edu.bd | M17: =IF($A17="","",$D17) -> 01717172837 | N17: =IF($K17="","",COUNTIFS($K$2:$K17,$K17))
F18: =IF(TRIM(E18)="","No","Yes") -> No | H18: =IF(TRIM(G18)="","No","Yes") -> No | J18: =IF($A18="","",$A18) | K18: =$E18 | L18: =IF($A18="","",$C18) | M18: =IF($A18="","",$D18) | N18: =IF($K18="","",COUNTIFS($K$2:$K18,$K18))
F19: =IF(TRIM(E19)="","No","Yes") -> No | H19: =IF(TRIM(G19)="","No","Yes") -> No | J19: =IF($A19="","",$A19) | K19: =$E19 | L19: =IF($A19="","",$C19) | M19: =IF($A19="","",$D19) | N19: =IF($K19="","",COUNTIFS($K$2:$K19,$K19))
F20: =IF(TRIM(E20)="","No","Yes") -> No | H20: =IF(TRIM(G20)="","No","Yes") -> No | J20: =IF($A20="","",$A20) | K20: =$E20 | L20: =IF($A20="","",$C20) | M20: =IF($A20="","",$D20) | N20: =IF($K20="","",COUNTIFS($K$2:$K20,$K20))
F21: =IF(TRIM(E21)="","No","Yes") -> No | H21: =IF(TRIM(G21)="","No","Yes") -> No | J21: =IF($A21="","",$A21) | K21: =$E21 | L21: =IF($A21="","",$C21) | M21: =IF($A21="","",$D21) | N21: =IF($K21="","",COUNTIFS($K$2:$K21,$K21))
F22: =IF(TRIM(E22)="","No","Yes") -> No | H22: =IF(TRIM(G22)="","No","Yes") -> No | J22: =IF($A22="","",$A22) | K22: =$E22 | L22: =IF($A22="","",$C22) | M22: =IF($A22="","",$D22) | N22: =IF($K22="","",COUNTIFS($K$2:$K22,$K22))
F23: =IF(TRIM(E23)="","No","Yes") -> No | H23: =IF(TRIM(G23)="","No","Yes") -> No | J23: =IF($A23="","",$A23) | K23: =$E23 | L23: =IF($A23="","",$C23) | M23: =IF($A23="","",$D23) | N23: =IF($K23="","",COUNTIFS($K$2:$K23,$K23))
F24: =IF(TRIM(E24)="","No","Yes") -> No | H24: =IF(TRIM(G24)="","No","Yes") -> No | J24: =IF($A24="","",$A24) | K24: =$E24 | L24: =IF($A24="","",$C24) | M24: =IF($A24="","",$D24) | N24: =IF($K24="","",COUNTIFS($K$2:$K24,$K24))
F25: =IF(TRIM(E25)="","No","Yes") -> No | H25: =IF(TRIM(G25)="","No","Yes") -> No | J25: =IF($A25="","",$A25) | K25: =$E25 | L25: =IF($A25="","",$C25) | M25: =IF($A25="","",$D25) | N25: =IF($K25="","",COUNTIFS($K$2:$K25,$K25))
F26: =IF(TRIM(E26)="","No","Yes") -> No | H26: =IF(TRIM(G26)="","No","Yes") -> No | J26: =IF($A26="","",$A26) | K26: =$E26 | L26: =IF($A26="","",$C26) | M26: =IF($A26="","",$D26) | N26: =IF($K26="","",COUNTIFS($K$2:$K26,$K26))
F27: =IF(TRIM(E27)="","No","Yes") -> No | H27: =IF(TRIM(G27)="","No","Yes") -> No | J27: =IF($A27="","",$A27) | K27: =$E27 | L27: =IF($A27="","",$C27) | M27: =IF($A27="","",$D27) | N27: =IF($K27="","",COUNTIFS($K$2:$K27,$K27))
F28: =IF(TRIM(E28)="","No","Yes") -> No | H28: =IF(TRIM(G28)="","No","Yes") -> No | J28: =IF($A28="","",$A28) | K28: =$E28 | L28: =IF($A28="","",$C28) | M28: =IF($A28="","",$D28) | N28: =IF($K28="","",COUNTIFS($K$2:$K28,$K28))
F29: =IF(TRIM(E29)="","No","Yes") -> No | H29: =IF(TRIM(G29)="","No","Yes") -> No | J29: =IF($A29="","",$A29) | K29: =$E29 | L29: =IF($A29="","",$C29) | M29: =IF($A29="","",$D29) | N29: =IF($K29="","",COUNTIFS($K$2:$K29,$K29))
... F201: =IF(TRIM(E201)="","No","Yes") -> No | H201: =IF(TRIM(G201)="","No","Yes") -> No | J201: =IF($A201="","",$A201) | K201: =$E201 | L201: =IF($A201="","",$C201) | M201: =IF($A201="","",$D201) | N201: =IF($K201="","",COUNTIFS($K$2:$K201,$K201))
J202: =IF($A2="","",$A2) -> Prof. Dr. Muhammad Golam Kibria | K202: =$G2 | L202: =IF($A2="","",$C2) -> golam.kibria@ulab.edu.bd | M202: =IF($A2="","",$D2) -> 01771122144 | N202: =IF($K202="","",COUNTIFS($K$2:$K202,$K202))
J203: =IF($A3="","",$A3) -> Prof. Dr. Nafees Mansoor | K203: =$G3 | L203: =IF($A3="","",$C3) -> nafees.mansoor@ulab.edu.bd | M203: =IF($A3="","",$D3) -> 01879242323 | N203: =IF($K203="","",COUNTIFS($K$2:$K203,$K203))
J204: =IF($A4="","",$A4) -> Anwarul Haque Joarder | K204: =$G4 | L204: =IF($A4="","",$C4) -> anwar.joarder@ulab.edu.bd | M204: =IF($A4="","",$D4) -> 01977000805 | N204: =IF($K204="","",COUNTIFS($K$2:$K204,$K204))
J205: =IF($A5="","",$A5) -> Dr. T. M Abul Kalam Azad | K205: =$G5 | L205: =IF($A5="","",$C5) -> abul.kalam@ulab.edu.bd | M205: =IF($A5="","",$D5) -> 01789379752 | N205: =IF($K205="","",COUNTIFS($K$2:$K205,$K205))
J206: =IF($A6="","",$A6) -> Dr. Rezwan Al Islam Khan | K206: =$G6 | L206: =IF($A6="","",$C6) -> rezwan.islam@ulab.edu.bd | M206: =IF($A6="","",$D6) -> 01712530199 | N206: =IF($K206="","",COUNTIFS($K$2:$K206,$K206))
J207: =IF($A7="","",$A7) -> Dr. Ayesha Akter Lata | K207: =$G7 -> T4P3 | L207: =IF($A7="","",$C7) -> ayesha.akter@ulab.edu.bd | M207: =IF($A7="","",$D7) -> 01856412501 | N207: =IF($K207="","",COUNTIFS($K$2:$K207,$K207)) -> 1
J208: =IF($A8="","",$A8) -> Dr. Al Amin Sheikh | K208: =$G8 -> T3P3 | L208: =IF($A8="","",$C8) -> taskia.khatun@ulab.edu.bd | M208: =IF($A8="","",$D8) -> 01701564663 | N208: =IF($K208="","",COUNTIFS($K$2:$K208,$K208)) -> 1
J209: =IF($A9="","",$A9) -> Dr. Mst. Taskia Khatun | K209: =$G9 | L209: =IF($A9="","",$C9) -> alamin.sheikh@ulab.edu.bd | M209: =IF($A9="","",$D9) -> 01764912222 | N209: =IF($K209="","",COUNTIFS($K$2:$K209,$K209))
J210: =IF($A10="","",$A10) -> Dr. Nafiz Jaidye | K210: =$G10 -> T3P5 | L210: =IF($A10="","",$C10) -> nafiz.jaidye@ulab.edu.bd | M210: =IF($A10="","",$D10) -> 01889121516 | N210: =IF($K210="","",COUNTIFS($K$2:$K210,$K210)) -> 1
J211: =IF($A11="","",$A11) -> Raihan Kibria | K211: =$G11 -> T4P4 | L211: =IF($A11="","",$C11) -> raihan.kibria@ulab.edu.bd | M211: =IF($A11="","",$D11) -> 01819417956 | N211: =IF($K211="","",COUNTIFS($K$2:$K211,$K211)) -> 1
...

Sheet Junior Faculty
A1: Name | B1: Designation | C1: Email | D1: Mobile | E1: Session 1 | F1: Assigned | G1: Session 2 | H1: Assigned | J1: Helper: Name | K1: Helper: Session Code | L1: Helper: Email | M1: Helper: Mobile | N1: Helper: Order
A2: Suravi Akhter | B2: Lecturer, CSE | C2: suravi.akhter@ulab.edu.bd | D2: 01308395394 | E2: T1P1 | F2: =IF(TRIM(E2)="","No","Yes") -> Yes | H2: =IF(TRIM(G2)="","No","Yes") -> No | J2: =IF($A2="","",$A2) -> Suravi Akhter | K2: =$E2 -> T1P1 | L2: =IF($A2="","",$C2) -> suravi.akhter@ulab.edu.bd | M2: =IF($A2="","",$D2) -> 01308395394 | N2: =IF($K2="","",COUNTIFS($K$2:$K2,$K2)) -> 1
A3: Nazmul Abdal | B3: Lecturer, CSE | C3: nazmul.abdal@ulab.edu.bd | D3: 01752813855 | E3: T1P2 | F3: =IF(TRIM(E3)="","No","Yes") -> Yes | G3: T3P3 | H3: =IF(TRIM(G3)="","No","Yes") -> Yes | J3: =IF($A3="","",$A3) -> Nazmul Abdal | K3: =$E3 -> T1P2 | L3: =IF($A3="","",$C3) -> nazmul.abdal@ulab.edu.bd | M3: =IF($A3="","",$D3) -> 01752813855 | N3: =IF($K3="","",COUNTIFS($K$2:$K3,$K3)) -> 1
A4: Fatema Khan | B4: Lecturer, CSE | C4: fatema.khan@ulab.edu.bd | D4: 01781527079 | E4: T1P3 | F4: =IF(TRIM(E4)="","No","Yes") -> Yes | G4: T3P1 | H4: =IF(TRIM(G4)="","No","Yes") -> Yes | J4: =IF($A4="","",$A4) -> Fatema Khan | K4: =$E4 -> T1P3 | L4: =IF($A4="","",$C4) -> fatema.khan@ulab.edu.bd | M4: =IF($A4="","",$D4) -> 01781527079 | N4: =IF($K4="","",COUNTIFS($K$2:$K4,$K4)) -> 1
A5: Md Kaviul Hossain | B5: Lecturer, CSE | C5: kaviul.hossain@ulab.edu.bd | D5: 01775520904 | E5: T2P1 | F5: =IF(TRIM(E5)="","No","Yes") -> Yes | H5: =IF(TRIM(G5)="","No","Yes") -> No | J5: =IF($A5="","",$A5) -> Md Kaviul Hossain | K5: =$E5 -> T2P1 | L5: =IF($A5="","",$C5) -> kaviul.hossain@ulab.edu.bd | M5: =IF($A5="","",$D5) -> 01775520904 | N5: =IF($K5="","",COUNTIFS($K$2:$K5,$K5)) -> 1
A6: Nasir Uddin Ahmed | B6: Lecturer, CSE | C6: nasir.uddin1@ulab.edu.bd | D6: 01818009809 | E6: T2P2 | F6: =IF(TRIM(E6)="","No","Yes") -> Yes | G6: T2P4 | H6: =IF(TRIM(G6)="","No","Yes") -> Yes | J6: =IF($A6="","",$A6) -> Nasir Uddin Ahmed | K6: =$E6 -> T2P2 | L6: =IF($A6="","",$C6) -> nasir.uddin1@ulab.edu.bd | M6: =IF($A6="","",$D6) -> 01818009809 | N6: =IF($K6="","",COUNTIFS($K$2:$K6,$K6)) -> 1
A7: Wahida Ferdose Urmi | B7: Lecturer, CSE | C7: wahida.ferdose@ulab.edu.bd | D7: 01756629803 | E7: T2P3 | F7: =IF(TRIM(E7)="","No","Yes") -> Yes | G7: T2P3 | H7: =IF(TRIM(G7)="","No","Yes") -> Yes | J7: =IF($A7="","",$A7) -> Wahida Ferdose Urmi | K7: =$E7 -> T2P3 | L7: =IF($A7="","",$C7) -> wahida.ferdose@ulab.edu.bd | M7: =IF($A7="","",$D7) -> 01756629803 | N7: =IF($K7="","",COUNTIFS($K$2:$K7,$K7)) -> 1
A8: Shah Jafor Sadeek Quaderi | B8: Lecturer, CSE | C8: jafor.sadeek@ulab.edu.bd | D8: 01725828062 | E8: T2P4 | F8: =IF(TRIM(E8)="","No","Yes") -> Yes | G8: T2P2 | H8: =IF(TRIM(G8)="","No","Yes") -> Yes | J8: =IF($A8="","",$A8) -> Shah Jafor Sadeek Quaderi | K8: =$E8 -> T2P4 | L8: =IF($A8="","",$C8) -> jafor.sadeek@ulab.edu.bd | M8: =IF($A8="","",$D8) -> 01725828062 | N8: =IF($K8="","",COUNTIFS($K$2:$K8,$K8)) -> 1
A9: Dewan Ahmed Muhtasim | B9: Lecturer, CSE | C9: ahmed.muhtasim@ulab.edu.bd | D9: 01602654504 | F9: =IF(TRIM(E9)="","No","Yes") -> No | G9: T2P1 | H9: =IF(TRIM(G9)="","No","Yes") -> Yes | J9: =IF($A9="","",$A9) -> Dewan Ahmed Muhtasim | K9: =$E9 | L9: =IF($A9="","",$C9) -> ahmed.muhtasim@ulab.edu.bd | M9: =IF($A9="","",$D9) -> 01602654504 | N9: =IF($K9="","",COUNTIFS($K$2:$K9,$K9))
A10: Atanu Shuvam Roy | B10: Lecturer, CSE | C10: atanu.shuvam@ulab.edu.bd | D10: 01937545261 | E10: T3P1 | F10: =IF(TRIM(E10)="","No","Yes") -> Yes | G10: T1P3 | H10: =IF(TRIM(G10)="","No","Yes") -> Yes | J10: =IF($A10="","",$A10) -> Atanu Shuvam Roy | K10: =$E10 -> T3P1 | L10: =IF($A10="","",$C10) -> atanu.shuvam@ulab.edu.bd | M10: =IF($A10="","",$D10) -> 01937545261 | N10: =IF($K10="","",COUNTIFS($K$2:$K10,$K10)) -> 1
A11: Foysal Ahmed | B11: Lecturer, CSE | C11: foysal.ahmed@ulab.edu.bd | D11: 01632917360 | F11: =IF(TRIM(E11)="","No","Yes") -> No | G11: T1P2 | H11: =IF(TRIM(G11)="","No","Yes") -> Yes | J11: =IF($A11="","",$A11) -> Foysal Ahmed | K11: =$E11 | L11: =IF($A11="","",$C11) -> foysal.ahmed@ulab.edu.bd | M11: =IF($A11="","",$D11) -> 01632917360 | N11: =IF($K11="","",COUNTIFS($K$2:$K11,$K11))
A12: Abir Bin Yousuf | B12: Lecturer, CSE | C12: abir.yousuf@ulab.edu.bd | D12: 01628312807 | E12: T3P3 | F12: =IF(TRIM(E12)="","No","Yes") -> Yes | G12: T1P1 | H12: =IF(TRIM(G12)="","No","Yes") -> Yes | J12: =IF($A12="","",$A12) -> Abir Bin Yousuf | K12: =$E12 -> T3P3 | L12: =IF($A12="","",$C12) -> abir.yousuf@ulab.edu.bd | M12: =IF($A12="","",$D12) -> 01628312807 | N12: =IF($K12="","",COUNTIFS($K$2:$K12,$K12)) -> 1
A13: A O M Shamsuddoha | B13: Lecturer, EEE | C13: shamsud.doha@ulab.edu.bd | D13: 01982279906 | F13: =IF(TRIM(E13)="","No","Yes") -> No | G13: T4P6 | H13: =IF(TRIM(G13)="","No","Yes") -> Yes | J13: =IF($A13="","",$A13) -> A O M Shamsuddoha | K13: =$E13 | L13: =IF($A13="","",$C13) -> shamsud.doha@ulab.edu.bd | M13: =IF($A13="","",$D13) -> 01982279906 | N13: =IF($K13="","",COUNTIFS($K$2:$K13,$K13))
A14: Abdullah Md. Zobayer | B14: Lecturer, EEE | C14: abdullah.zobayer@ulab.edu.bd | D14: 01921999286 | E14: T3P5 | F14: =IF(TRIM(E14)="","No","Yes") -> Yes | G14: T4P5 | H14: =IF(TRIM(G14)="","No","Yes") -> Yes | J14: =IF($A14="","",$A14) -> Abdullah Md. Zobayer | K14: =$E14 -> T3P5 | L14: =IF($A14="","",$C14) -> abdullah.zobayer@ulab.edu.bd | M14: =IF($A14="","",$D14) -> 01921999286 | N14: =IF($K14="","",COUNTIFS($K$2:$K14,$K14)) -> 1
A15: Md. Monzurul Haque | B15: Lecturer, EEE | C15: monzurul.haque@ulab.edu.bd | D15: 01621853028 | E15: T4P1 | F15: =IF(TRIM(E15)="","No","Yes") -> Yes | G15: T4P4 | H15: =IF(TRIM(G15)="","No","Yes") -> Yes | J15: =IF($A15="","",$A15) -> Md. Monzurul Haque | K15: =$E15 -> T4P1 | L15: =IF($A15="","",$C15) -> monzurul.haque@ulab.edu.bd | M15: =IF($A15="","",$D15) -> 01621853028 | N15: =IF($K15="","",COUNTIFS($K$2:$K15,$K15)) -> 1
A16: Imran Hossain | B16: Lecturer, EEE | C16: imran.hossain3@ulab.edu.bd | D16: 01621853028 | E16: T4P2 | F16: =IF(TRIM(E16)="","No","Yes") -> Yes | G16: T4P3 | H16: =IF(TRIM(G16)="","No","Yes") -> Yes | J16: =IF($A16="","",$A16) -> Imran Hossain | K16: =$E16 -> T4P2 | L16: =IF($A16="","",$C16) -> imran.hossain3@ulab.edu.bd | M16: =IF($A16="","",$D16) -> 01621853028 | N16: =IF($K16="","",COUNTIFS($K$2:$K16,$K16)) -> 1
F17: =IF(TRIM(E17)="","No","Yes") -> No | H17: =IF(TRIM(G17)="","No","Yes") -> No | J17: =IF($A17="","",$A17) | K17: =$E17 | L17: =IF($A17="","",$C17) | M17: =IF($A17="","",$D17) | N17: =IF($K17="","",COUNTIFS($K$2:$K17,$K17))
F18: =IF(TRIM(E18)="","No","Yes") -> No | H18: =IF(TRIM(G18)="","No","Yes") -> No | J18: =IF($A18="","",$A18) | K18: =$E18 | L18: =IF($A18="","",$C18) | M18: =IF($A18="","",$D18) | N18: =IF($K18="","",COUNTIFS($K$2:$K18,$K18))
F19: =IF(TRIM(E19)="","No","Yes") -> No | H19: =IF(TRIM(G19)="","No","Yes") -> No | J19: =IF($A19="","",$A19) | K19: =$E19 | L19: =IF($A19="","",$C19) | M19: =IF($A19="","",$D19) | N19: =IF($K19="","",COUNTIFS($K$2:$K19,$K19))
F20: =IF(TRIM(E20)="","No","Yes") -> No | H20: =IF(TRIM(G20)="","No","Yes") -> No | J20: =IF($A20="","",$A20) | K20: =$E20 | L20: =IF($A20="","",$C20) | M20: =IF($A20="","",$D20) | N20: =IF($K20="","",COUNTIFS($K$2:$K20,$K20))
F21: =IF(TRIM(E21)="","No","Yes") -> No | H21: =IF(TRIM(G21)="","No","Yes") -> No | J21: =IF($A21="","",$A21) | K21: =$E21 | L21: =IF($A21="","",$C21) | M21: =IF($A21="","",$D21) | N21: =IF($K21="","",COUNTIFS($K$2:$K21,$K21))
F22: =IF(TRIM(E22)="","No","Yes") -> No | H22: =IF(TRIM(G22)="","No","Yes") -> No | J22: =IF($A22="","",$A22) | K22: =$E22 | L22: =IF($A22="","",$C22) | M22: =IF($A22="","",$D22) | N22: =IF($K22="","",COUNTIFS($K$2:$K22,$K22))
F23: =IF(TRIM(E23)="","No","Yes") -> No | H23: =IF(TRIM(G23)="","No","Yes") -> No | J23: =IF($A23="","",$A23) | K23: =$E23 | L23: =IF($A23="","",$C23) | M23: =IF($A23="","",$D23) | N23: =IF($K23="","",COUNTIFS($K$2:$K23,$K23))
F24: =IF(TRIM(E24)="","No","Yes") -> No | H24: =IF(TRIM(G24)="","No","Yes") -> No | J24: =IF($A24="","",$A24) | K24: =$E24 | L24: =IF($A24="","",$C24) | M24: =IF($A24="","",$D24) | N24: =IF($K24="","",COUNTIFS($K$2:$K24,$K24))
F25: =IF(TRIM(E25)="","No","Yes") -> No | H25: =IF(TRIM(G25)="","No","Yes") -> No | J25: =IF($A25="","",$A25) | K25: =$E25 | L25: =IF($A25="","",$C25) | M25: =IF($A25="","",$D25) | N25: =IF($K25="","",COUNTIFS($K$2:$K25,$K25))
F26: =IF(TRIM(E26)="","No","Yes") -> No | H26: =IF(TRIM(G26)="","No","Yes") -> No | J26: =IF($A26="","",$A26) | K26: =$E26 | L26: =IF($A26="","",$C26) | M26: =IF($A26="","",$D26) | N26: =IF($K26="","",COUNTIFS($K$2:$K26,$K26))
F27: =IF(TRIM(E27)="","No","Yes") -> No | H27: =IF(TRIM(G27)="","No","Yes") -> No | J27: =IF($A27="","",$A27) | K27: =$E27 | L27: =IF($A27="","",$C27) | M27: =IF($A27="","",$D27) | N27: =IF($K27="","",COUNTIFS($K$2:$K27,$K27))
F28: =IF(TRIM(E28)="","No","Yes") -> No | H28: =IF(TRIM(G28)="","No","Yes") -> No | J28: =IF($A28="","",$A28) | K28: =$E28 | L28: =IF($A28="","",$C28) | M28: =IF($A28="","",$D28) | N28: =IF($K28="","",COUNTIFS($K$2:$K28,$K28))
... F201: =IF(TRIM(E201)="","No","Yes") -> No | H201: =IF(TRIM(G201)="","No","Yes") -> No | J201: =IF($A201="","",$A201) | K201: =$E201 | L201: =IF($A201="","",$C201) | M201: =IF($A201="","",$D201) | N201: =IF($K201="","",COUNTIFS($K$2:$K201,$K201))
J202: =IF($A2="","",$A2) -> Suravi Akhter | K202: =$G2 | L202: =IF($A2="","",$C2) -> suravi.akhter@ulab.edu.bd | M202: =IF($A2="","",$D2) -> 01308395394 | N202: =IF($K202="","",COUNTIFS($K$2:$K202,$K202))
J203: =IF($A3="","",$A3) -> Nazmul Abdal | K203: =$G3 -> T3P3 | L203: =IF($A3="","",$C3) -> nazmul.abdal@ulab.edu.bd | M203: =IF($A3="","",$D3) -> 01752813855 | N203: =IF($K203="","",COUNTIFS($K$2:$K203,$K203)) -> 2
J204: =IF($A4="","",$A4) -> Fatema Khan | K204: =$G4 -> T3P1 | L204: =IF($A4="","",$C4) -> fatema.khan@ulab.edu.bd | M204: =IF($A4="","",$D4) -> 01781527079 | N204: =IF($K204="","",COUNTIFS($K$2:$K204,$K204)) -> 2
J205: =IF($A5="","",$A5) -> Md Kaviul Hossain | K205: =$G5 | L205: =IF($A5="","",$C5) -> kaviul.hossain@ulab.edu.bd | M205: =IF($A5="","",$D5) -> 01775520904 | N205: =IF($K205="","",COUNTIFS($K$2:$K205,$K205))
J206: =IF($A6="","",$A6) -> Nasir Uddin Ahmed | K206: =$G6 -> T2P4 | L206: =IF($A6="","",$C6) -> nasir.uddin1@ulab.edu.bd | M206: =IF($A6="","",$D6) -> 01818009809 | N206: =IF($K206="","",COUNTIFS($K$2:$K206,$K206)) -> 2
J207: =IF($A7="","",$A7) -> Wahida Ferdose Urmi | K207: =$G7 -> T2P3 | L207: =IF($A7="","",$C7) -> wahida.ferdose@ulab.edu.bd | M207: =IF($A7="","",$D7) -> 01756629803 | N207: =IF($K207="","",COUNTIFS($K$2:$K207,$K207)) -> 2
J208: =IF($A8="","",$A8) -> Shah Jafor Sadeek Quaderi | K208: =$G8 -> T2P2 | L208: =IF($A8="","",$C8) -> jafor.sadeek@ulab.edu.bd | M208: =IF($A8="","",$D8) -> 01725828062 | N208: =IF($K208="","",COUNTIFS($K$2:$K208,$K208)) -> 2
J209: =IF($A9="","",$A9) -> Dewan Ahmed Muhtasim | K209: =$G9 -> T2P1 | L209: =IF($A9="","",$C9) -> ahmed.muhtasim@ulab.edu.bd | M209: =IF($A9="","",$D9) -> 01602654504 | N209: =IF($K209="","",COUNTIFS($K$2:$K209,$K209)) -> 2
J210: =IF($A10="","",$A10) -> Atanu Shuvam Roy | K210: =$G10 -> T1P3 | L210: =IF($A10="","",$C10) -> atanu.shuvam@ulab.edu.bd | M210: =IF($A10="","",$D10) -> 01937545261 | N210: =IF($K210="","",COUNTIFS($K$2:$K210,$K210)) -> 2
J211: =IF($A11="","",$A11) -> Foysal Ahmed | K211: =$G11 -> T1P2 | L211: =IF($A11="","",$C11) -> foysal.ahmed@ulab.edu.bd | M211: =IF($A11="","",$D11) -> 01632917360 | N211: =IF($K211="","",COUNTIFS($K$2:$K211,$K211)) -> 2
J212: =IF($A12="","",$A12) -> Abir Bin Yousuf | K212: =$G12 -> T1P1 | L212: =IF($A12="","",$C12) -> abir.yousuf@ulab.edu.bd | M212: =IF($A12="","",$D12) -> 01628312807 | N212: =IF($K212="","",COUNTIFS($K$2:$K212,$K212)) -> 2
...

Sheet Chairs
A1: Name | B1: Designation | C1: Email | D1: Mobile | E1: Session 1 | F1: Assigned | G1: Session 2 | H1: Assigned | J1: Helper: Name | K1: Helper: Session Code | L1: Helper: Email | M1: Helper: Mobile | N1: Helper: Order
A2: Dr. Md.Ruhul Amin | B2: Southeast University | C2: dr.mdruhulamin@seu.edu.bd | D2: 01710949921 | E2: T1P1 | F2: =IF(TRIM(E2)="","No","Yes") -> Yes | H2: =IF(TRIM(G2)="","No","Yes") -> No | J2: =IF($A2="","",$A2) -> Dr. Md.Ruhul Amin | K2: =$E2 -> T1P1 | L2: =IF($A2="","",$C2) -> dr.mdruhulamin@seu.edu.bd | M2: =IF($A2="","",$D2) -> 01710949921 | N2: =IF($K2="","",COUNTIFS($K$2:$K2,$K2)) -> 1
A3: Dr. Mohammed Ashikur Rahman | B3: Southeast Universuty | C3: ashikur.rahman@seu.edu.bd | D3: 01735524483 | E3: T2P1 | F3: =IF(TRIM(E3)="","No","Yes") -> Yes | H3: =IF(TRIM(G3)="","No","Yes") -> No | J3: =IF($A3="","",$A3) -> Dr. Mohammed Ashikur Rahman | K3: =$E3 -> T2P1 | L3: =IF($A3="","",$C3) -> ashikur.rahman@seu.edu.bd | M3: =IF($A3="","",$D3) -> 01735524483 | N3: =IF($K3="","",COUNTIFS($K$2:$K3,$K3)) -> 1
A4: Prof. Dr. Ishtiak Al Mamoon | B4: IUBAT | C4: Ishtiak.cse@iubat.edu | D4: 01713229860 | E4: T4P1 | F4: =IF(TRIM(E4)="","No","Yes") -> Yes | H4: =IF(TRIM(G4)="","No","Yes") -> No | J4: =IF($A4="","",$A4) -> Prof. Dr. Ishtiak Al Mamoon | K4: =$E4 -> T4P1 | L4: =IF($A4="","",$C4) -> Ishtiak.cse@iubat.edu | M4: =IF($A4="","",$D4) -> 01713229860 | N4: =IF($K4="","",COUNTIFS($K$2:$K4,$K4)) -> 1
A5: Prof. Dr. Ahmed Al Mansur | B5: Bangladesh University of Business and Technology (BUBT) | C5: mansur.eee@bubt.edu.bd | D5: 01715020314 | E5: T4P2 | F5: =IF(TRIM(E5)="","No","Yes") -> Yes | H5: =IF(TRIM(G5)="","No","Yes") -> No | J5: =IF($A5="","",$A5) -> Prof. Dr. Ahmed Al Mansur | K5: =$E5 -> T4P2 | L5: =IF($A5="","",$C5) -> mansur.eee@bubt.edu.bd | M5: =IF($A5="","",$D5) -> 01715020314 | N5: =IF($K5="","",COUNTIFS($K$2:$K5,$K5)) -> 1
A6: Prof. Dr. Kamruddin Nur | B6: American International University-Bangladesh | C6: kamruddin.nur@gmail.com | D6: 01777354323 | E6: T1P2 | F6: =IF(TRIM(E6)="","No","Yes") -> Yes | H6: =IF(TRIM(G6)="","No","Yes") -> No | J6: =IF($A6="","",$A6) -> Prof. Dr. Kamruddin Nur | K6: =$E6 -> T1P2 | L6: =IF($A6="","",$C6) -> kamruddin.nur@gmail.com | M6: =IF($A6="","",$D6) -> 01777354323 | N6: =IF($K6="","",COUNTIFS($K$2:$K6,$K6)) -> 1
A7: Dr. Nahid Akhter Jahan | B7: Brac University | C7: nahid.jahan@bracu.ac.bd | D7: 01828141026 | E7: T1P3 | F7: =IF(TRIM(E7)="","No","Yes") -> Yes | H7: =IF(TRIM(G7)="","No","Yes") -> No | J7: =IF($A7="","",$A7) -> Dr. Nahid Akhter Jahan | K7: =$E7 -> T1P3 | L7: =IF($A7="","",$C7) -> nahid.jahan@bracu.ac.bd | M7: =IF($A7="","",$D7) -> 01828141026 | N7: =IF($K7="","",COUNTIFS($K$2:$K7,$K7)) -> 1
A8: Dr. Mirza Rasheduzzaman | B8: BRAC University | C8: mirza.rasheduzzaman@gmail.com | D8: 01787736780 | E8: T2P4 | F8: =IF(TRIM(E8)="","No","Yes") -> Yes | H8: =IF(TRIM(G8)="","No","Yes") -> No | J8: =IF($A8="","",$A8) -> Dr. Mirza Rasheduzzaman | K8: =$E8 -> T2P4 | L8: =IF($A8="","",$C8) -> mirza.rasheduzzaman@gmail.com | M8: =IF($A8="","",$D8) -> 01787736780 | N8: =IF($K8="","",COUNTIFS($K$2:$K8,$K8)) -> 1
A9: Dr. Mohammad Rifat Ahmmad Rashid | B9: East West University | C9: rifat.rashid@ewubd.edu | D9: 01314447616 | E9: T3P3 | F9: =IF(TRIM(E9)="","No","Yes") -> Yes | H9: =IF(TRIM(G9)="","No","Yes") -> No | J9: =IF($A9="","",$A9) -> Dr. Mohammad Rifat Ahmmad Rashid | K9: =$E9 -> T3P3 | L9: =IF($A9="","",$C9) -> rifat.rashid@ewubd.edu | M9: =IF($A9="","",$D9) -> 01314447616 | N9: =IF($K9="","",COUNTIFS($K$2:$K9,$K9)) -> 1
A10: Prof. Dr. Engr. Muhibul Haque Bhuyan | B10: American International University-Bangladesh | C10: muhibulhb@aiub.edu | D10: 01815657346 | E10: T4P4 | F10: =IF(TRIM(E10)="","No","Yes") -> Yes | H10: =IF(TRIM(G10)="","No","Yes") -> No | J10: =IF($A10="","",$A10) -> Prof. Dr. Engr. Muhibul Haque Bhuyan | K10: =$E10 -> T4P4 | L10: =IF($A10="","",$C10) -> muhibulhb@aiub.edu | M10: =IF($A10="","",$D10) -> 01815657346 | N10: =IF($K10="","",COUNTIFS($K$2:$K10,$K10)) -> 1
A11: Dr. Khairul Alam | B11: Dept. of Electrical & Electronic Engineering East West University | C11: kalam@ewubd.edu | D11: 01713458911 | E11: T4P3 | F11: =IF(TRIM(E11)="","No","Yes") -> Yes | H11: =IF(TRIM(G11)="","No","Yes") -> No | J11: =IF($A11="","",$A11) -> Dr. Khairul Alam | K11: =$E11 -> T4P3 | L11: =IF($A11="","",$C11) -> kalam@ewubd.edu | M11: =IF($A11="","",$D11) -> 01713458911 | N11: =IF($K11="","",COUNTIFS($K$2:$K11,$K11)) -> 1
A12: Dr. Sifat Momen | B12: North South University | C12: sifat.momen@northsouth.edu | D12: 01754119999 | E12: T3P5 | F12: =IF(TRIM(E12)="","No","Yes") -> Yes | H12: =IF(TRIM(G12)="","No","Yes") -> No | J12: =IF($A12="","",$A12) -> Dr. Sifat Momen | K12: =$E12 -> T3P5 | L12: =IF($A12="","",$C12) -> sifat.momen@northsouth.edu | M12: =IF($A12="","",$D12) -> 01754119999 | N12: =IF($K12="","",COUNTIFS($K$2:$K12,$K12)) -> 1
A13: Dr. Mohammad Nurul Huda | B13: United International University | C13: mnh@cse.uiu.ac.bd | D13: 01673476433 | E13: T2P2 | F13: =IF(TRIM(E13)="","No","Yes") -> Yes | H13: =IF(TRIM(G13)="","No","Yes") -> No | J13: =IF($A13="","",$A13) -> Dr. Mohammad Nurul Huda | K13: =$E13 -> T2P2 | L13: =IF($A13="","",$C13) -> mnh@cse.uiu.ac.bd | M13: =IF($A13="","",$D13) -> 01673476433 | N13: =IF($K13="","",COUNTIFS($K$2:$K13,$K13)) -> 1
... A20: Dr. Anwarul Haque Joarder | B20: Professor, CSE | C20: anwar.joarder@ulab.edu.bd | D20: 01977000805 | E20: IEEE Workshop | F20: =IF(TRIM(E20)="","No","Yes") -> Yes | H20: =IF(TRIM(G20)="","No","Yes") -> No | J20: =IF($A20="","",$A20) -> Dr. Anwarul Haque Joarder | K20: =$E20 -> IEEE Workshop | L20: =IF($A20="","",$C20) -> anwar.joarder@ulab.edu.bd | M20: =IF($A20="","",$D20) -> 01977000805 | N20: =IF($K20="","",COUNTIFS($K$2:$K20,$K20)) -> 1
A21: Dr. A. B. M. Sayeed Ud Doulah | B21: Associate Professor, EEE | C21: sayeed.doulah@seu.edu.bd | F21: =IF(TRIM(E21)="","No","Yes") -> No | H21: =IF(TRIM(G21)="","No","Yes") -> No | J21: =IF($A21="","",$A21) -> Dr. A. B. M. Sayeed Ud Doulah | K21: =$E21 | L21: =IF($A21="","",$C21) -> sayeed.doulah@seu.edu.bd | M21: =IF($A21="","",$D21) | N21: =IF($K21="","",COUNTIFS($K$2:$K21,$K21))
F22: =IF(TRIM(E22)="","No","Yes") -> No | H22: =IF(TRIM(G22)="","No","Yes") -> No | J22: =IF($A22="","",$A22) | K22: =$E22 | L22: =IF($A22="","",$C22) | M22: =IF($A22="","",$D22) | N22: =IF($K22="","",COUNTIFS($K$2:$K22,$K22))
F23: =IF(TRIM(E23)="","No","Yes") -> No | H23: =IF(TRIM(G23)="","No","Yes") -> No | J23: =IF($A23="","",$A23) | K23: =$E23 | L23: =IF($A23="","",$C23) | M23: =IF($A23="","",$D23) | N23: =IF($K23="","",COUNTIFS($K$2:$K23,$K23))
F24: =IF(TRIM(E24)="","No","Yes") -> No | H24: =IF(TRIM(G24)="","No","Yes") -> No | J24: =IF($A24="","",$A24) | K24: =$E24 | L24: =IF($A24="","",$C24) | M24: =IF($A24="","",$D24) | N24: =IF($K24="","",COUNTIFS($K$2:$K24,$K24))
F25: =IF(TRIM(E25)="","No","Yes") -> No | H25: =IF(TRIM(G25)="","No","Yes") -> No | J25: =IF($A25="","",$A25) | K25: =$E25 | L25: =IF($A25="","",$C25) | M25: =IF($A25="","",$D25) | N25: =IF($K25="","",COUNTIFS($K$2:$K25,$K25))
F26: =IF(TRIM(E26)="","No","Yes") -> No | H26: =IF(TRIM(G26)="","No","Yes") -> No | J26: =IF($A26="","",$A26) | K26: =$E26 | L26: =IF($A26="","",$C26) | M26: =IF($A26="","",$D26) | N26: =IF($K26="","",COUNTIFS($K$2:$K26,$K26))
F27: =IF(TRIM(E27)="","No","Yes") -> No | H27: =IF(TRIM(G27)="","No","Yes") -> No | J27: =IF($A27="","",$A27) | K27: =$E27 | L27: =IF($A27="","",$C27) | M27: =IF($A27="","",$D27) | N27: =IF($K27="","",COUNTIFS($K$2:$K27,$K27))
F28: =IF(TRIM(E28)="","No","Yes") -> No | H28: =IF(TRIM(G28)="","No","Yes") -> No | J28: =IF($A28="","",$A28) | K28: =$E28 | L28: =IF($A28="","",$C28) | M28: =IF($A28="","",$D28) | N28: =IF($K28="","",COUNTIFS($K$2:$K28,$K28))
F29: =IF(TRIM(E29)="","No","Yes") -> No | H29: =IF(TRIM(G29)="","No","Yes") -> No | J29: =IF($A29="","",$A29) | K29: =$E29 | L29: =IF($A29="","",$C29) | M29: =IF($A29="","",$D29) | N29: =IF($K29="","",COUNTIFS($K$2:$K29,$K29))
F30: =IF(TRIM(E30)="","No","Yes") -> No | H30: =IF(TRIM(G30)="","No","Yes") -> No | J30: =IF($A30="","",$A30) | K30: =$E30 | L30: =IF($A30="","",$C30) | M30: =IF($A30="","",$D30) | N30: =IF($K30="","",COUNTIFS($K$2:$K30,$K30))
F31: =IF(TRIM(E31)="","No","Yes") -> No | H31: =IF(TRIM(G31)="","No","Yes") -> No | J31: =IF($A31="","",$A31) | K31: =$E31 | L31: =IF($A31="","",$C31) | M31: =IF($A31="","",$D31) | N31: =IF($K31="","",COUNTIFS($K$2:$K31,$K31))
F32: =IF(TRIM(E32)="","No","Yes") -> No | H32: =IF(TRIM(G32)="","No","Yes") -> No | J32: =IF($A32="","",$A32) | K32: =$E32 | L32: =IF($A32="","",$C32) | M32: =IF($A32="","",$D32) | N32: =IF($K32="","",COUNTIFS($K$2:$K32,$K32))
F33: =IF(TRIM(E33)="","No","Yes") -> No | H33: =IF(TRIM(G33)="","No","Yes") -> No | J33: =IF($A33="","",$A33) | K33: =$E33 | L33: =IF($A33="","",$C33) | M33: =IF($A33="","",$D33) | N33: =IF($K33="","",COUNTIFS($K$2:$K33,$K33))
... F159: =IF(TRIM(E159)="","No","Yes") -> No | H159: =IF(TRIM(G159)="","No","Yes") -> No | J159: =IF($A159="","",$A159) | K159: =$E159 | L159: =IF($A159="","",$C159) | M159: =IF($A159="","",$D159) | N159: =IF($K159="","",COUNTIFS($K$2:$K159,$K159))
J160: =IF(#REF!="","",#REF!) -> #REF! | K160: =#REF! -> #REF! | L160: =IF(#REF!="","",#REF!) -> #REF! | M160: =IF(#REF!="","",#REF!) -> #REF! | N160: =IF($K160="","",COUNTIFS($K$2:$K160,$K160)) -> #REF!
J161: =IF(#REF!="","",#REF!) -> #REF! | K161: =#REF! -> #REF! | L161: =IF(#REF!="","",#REF!) -> #REF! | M161: =IF(#REF!="","",#REF!) -> #REF! | N161: =IF($K161="","",COUNTIFS($K$2:$K161,$K161)) -> #REF!
J162: =IF($A2="","",$A2) -> Dr. Md.Ruhul Amin | K162: =$G2 | L162: =IF($A2="","",$C2) -> dr.mdruhulamin@seu.edu.bd | M162: =IF($A2="","",$D2) -> 01710949921 | N162: =IF($K162="","",COUNTIFS($K$2:$K162,$K162))
J163: =IF($A3="","",$A3) -> Dr. Mohammed Ashikur Rahman | K163: =$G3 | L163: =IF($A3="","",$C3) -> ashikur.rahman@seu.edu.bd | M163: =IF($A3="","",$D3) -> 01735524483 | N163: =IF($K163="","",COUNTIFS($K$2:$K163,$K163))
J164: =IF(#REF!="","",#REF!) -> #REF! | K164: =#REF! -> #REF! | L164: =IF(#REF!="","",#REF!) -> #REF! | M164: =IF(#REF!="","",#REF!) -> #REF! | N164: =IF($K164="","",COUNTIFS($K$2:$K164,$K164)) -> #REF!
J165: =IF(#REF!="","",#REF!) -> #REF! | K165: =#REF! -> #REF! | L165: =IF(#REF!="","",#REF!) -> #REF! | M165: =IF(#REF!="","",#REF!) -> #REF! | N165: =IF($K165="","",COUNTIFS($K$2:$K165,$K165)) -> #REF!
J166: =IF($A4="","",$A4) -> Prof. Dr. Ishtiak Al Mamoon | K166: =$G4 | L166: =IF($A4="","",$C4) -> Ishtiak.cse@iubat.edu | M166: =IF($A4="","",$D4) -> 01713229860 | N166: =IF($K166="","",COUNTIFS($K$2:$K166,$K166))
J167: =IF(#REF!="","",#REF!) -> #REF! | K167: =#REF! -> #REF! | L167: =IF(#REF!="","",#REF!) -> #REF! | M167: =IF(#REF!="","",#REF!) -> #REF! | N167: =IF($K167="","",COUNTIFS($K$2:$K167,$K167)) -> #REF!
J168: =IF($A5="","",$A5) -> Prof. Dr. Ahmed Al Mansur | K168: =$G5 | L168: =IF($A5="","",$C5) -> mansur.eee@bubt.edu.bd | M168: =IF($A5="","",$D5) -> 01715020314 | N168: =IF($K168="","",COUNTIFS($K$2:$K168,$K168))
J169: =IF(#REF!="","",#REF!) -> #REF! | K169: =#REF! -> #REF! | L169: =IF(#REF!="","",#REF!) -> #REF! | M169: =IF(#REF!="","",#REF!) -> #REF! | N169: =IF($K169="","",COUNTIFS($K$2:$K169,$K169)) -> #REF!
J170: =IF($A6="","",$A6) -> Prof. Dr. Kamruddin Nur | K170: =$G6 | L170: =IF($A6="","",$C6) -> kamruddin.nur@gmail.com | M170: =IF($A6="","",$D6) -> 01777354323 | N170: =IF($K170="","",COUNTIFS($K$2:$K170,$K170))
J171: =IF(#REF!="","",#REF!) -> #REF! | K171: =#REF! -> #REF! | L171: =IF(#REF!="","",#REF!) -> #REF! | M171: =IF(#REF!="","",#REF!) -> #REF! | N171: =IF($K171="","",COUNTIFS($K$2:$K171,$K171)) -> #REF!
...

Sheet Papers
A1: ID | B1: Track | C1: Title | D1: Authors | E1: Emails | F1: Primary | G1: Session | H1: Assigned | I1: Order | J1: Chair Score (/50) | K1: Reviewer Score (/50) | L1: Total (/100) | M1: Rank
A2: 2 | B2: Computing | C2: Evaluating image upsampling strategies for downstream microscopy image classification | D2: Sakib Mohammad (Fairmont State University)*; Aalvee Asad Kausani (Fairmont State University); Md Noumil Tousif (Islamic University of Technology) | E2: smohammad@fairmontstate.edu; akausani@fairmontstate.edu; noumiltousif@iut-dhaka.edu | F2: smohammad@fairmontstate.edu | G2: T4P1 | H2: =IF(TRIM(G2)="","No","Yes") -> Yes | I2: =IF(TRIM(G2)="","",COUNTIFS($G$2:G2,G2)) -> 1 | J2: =IF(OR($A2="",TRIM($G2)=""),"",IFERROR(IF(INDEX(INDIRECT("'"&$G2&"'!F1:F100"),MATCH($A2,INDIRECT("'"&$G2&"'!A1:A100"),0))="","",INDEX(INDIRECT("'"&$G2&"'!F1:F100"),MATCH($A2,INDIRECT("'"&$G2&"'!A1:A100"),0))),"")) | K2: 35 | L2: =IF(COUNT(J2:K2)<2,"",J2+K2) | M2: =IF(L2="","",RANK(L2,$L$2:$L$201,0))
A3: 5 | B3: Computing | C3: A Hybrid Retrieval-Augmented Machine Learning Approach for AI-Generated Text Detection | D3: Md. Siam Ansary (Ahsanullah University of Science and Technology)*; SUMONA ISLAM ZERIN (Ahsanullah University of Science and Technology (AUST)) | E3: siamansary.aust@gmail.com; sumona.vnc@gmail.com | F3: siamansary.aust@gmail.com | G3: T4P1 | H3: =IF(TRIM(G3)="","No","Yes") -> Yes | I3: =IF(TRIM(G3)="","",COUNTIFS($G$2:G3,G3)) -> 2 | J3: =IF(OR($A3="",TRIM($G3)=""),"",IFERROR(IF(INDEX(INDIRECT("'"&$G3&"'!F1:F100"),MATCH($A3,INDIRECT("'"&$G3&"'!A1:A100"),0))="","",INDEX(INDIRECT("'"&$G3&"'!F1:F100"),MATCH($A3,INDIRECT("'"&$G3&"'!A1:A100"),0))),"")) | L3: =IF(COUNT(J3:K3)<2,"",J3+K3) | M3: =IF(L3="","",RANK(L3,$L$2:$L$201,0))
A4: 48 | B4: Computing | C4: CEC: A Non-Stationary Benchmarking Protocol for the Fair Evaluation of Metaheuristic Optimizers | D4: Hussain Mohammad Ricon (American International University-Bangladesh); Tabassum Alam (American International University-Bangladesh); Rifat Rudro (American International University-Bangladesh)*; Kamruddin Nur ( American International University-Bangladesh) | E4: 22-49911-3@student.aiub.edu; 22-49912-3@student.aiub.edu; mamun.rudro@aiub.edu; kamruddin@aiub.edu | F4: mamun.rudro@aiub.edu | G4: T4P4 | H4: =IF(TRIM(G4)="","No","Yes") -> Yes | I4: =IF(TRIM(G4)="","",COUNTIFS($G$2:G4,G4)) -> 1 | J4: =IF(OR($A4="",TRIM($G4)=""),"",IFERROR(IF(INDEX(INDIRECT("'"&$G4&"'!F1:F100"),MATCH($A4,INDIRECT("'"&$G4&"'!A1:A100"),0))="","",INDEX(INDIRECT("'"&$G4&"'!F1:F100"),MATCH($A4,INDIRECT("'"&$G4&"'!A1:A100"),0))),"")) | K4: 40 | L4: =IF(COUNT(J4:K4)<2,"",J4+K4) | M4: =IF(L4="","",RANK(L4,$L$2:$L$201,0))
A5: 49 | B5: Computing | C5: SPPC: Benchmarking Selenium, Playwright, Puppeteer, and Cypress for Energy-Efficient Web Automation | D5: MD. Zihaul Islam Zihan (American International University-Bangladesh); Al Israfil Niloy ( American International University-Bangladesh); Raid Ibney Hasan Arnob (American International University-Bangladesh); Rifat Rudro (American International University-Bangladesh)*; Kamruddin Nur (American International University-Bangladesh) | E5: 22-49229-3@student.aiub.edu; 22-49033-3@student.aiub.edu; 22-48357-3@student.aiub.edu; mamun.rudro@aiub.edu; kamruddin@aiub.edu | F5: mamun.rudro@aiub.edu | G5: T1P1 | H5: =IF(TRIM(G5)="","No","Yes") -> Yes | I5: =IF(TRIM(G5)="","",COUNTIFS($G$2:G5,G5)) -> 1 | J5: =IF(OR($A5="",TRIM($G5)=""),"",IFERROR(IF(INDEX(INDIRECT("'"&$G5&"'!F1:F100"),MATCH($A5,INDIRECT("'"&$G5&"'!A1:A100"),0))="","",INDEX(INDIRECT("'"&$G5&"'!F1:F100"),MATCH($A5,INDIRECT("'"&$G5&"'!A1:A100"),0))),"")) | L5: =IF(COUNT(J5:K5)<2,"",J5+K5) | M5: =IF(L5="","",RANK(L5,$L$2:$L$201,0))
A6: 58 | B6: Computing | C6: Explainable Machine Learning for Cross-Species Myeloid Biomarker Discovery in Glioblastoma | D6: MD Himel Kabir (American International University-Bangladesh); Shanjida Sultana (American International University-Bangladesh); MD Salauddin (American International University-Bangladesh); Rifat Rudro (American International University-Bangladesh)*; Kamruddin Nur (American International University-Bangladesh) | E6: 23-51481-1@student.aiub.edu; 23-51519-1@student.aiub.edu; 23-51479-1@student.aiub.edu; mamun.rudro@aiub.edu; kamruddin@aiub.edu | F6: mamun.rudro@aiub.edu | G6: T1P1 | H6: =IF(TRIM(G6)="","No","Yes") -> Yes | I6: =IF(TRIM(G6)="","",COUNTIFS($G$2:G6,G6)) -> 2 | J6: =IF(OR($A6="",TRIM($G6)=""),"",IFERROR(IF(INDEX(INDIRECT("'"&$G6&"'!F1:F100"),MATCH($A6,INDIRECT("'"&$G6&"'!A1:A100"),0))="","",INDEX(INDIRECT("'"&$G6&"'!F1:F100"),MATCH($A6,INDIRECT("'"&$G6&"'!A1:A100"),0))),"")) | L6: =IF(COUNT(J6:K6)<2,"",J6+K6) | M6: =IF(L6="","",RANK(L6,$L$2:$L$201,0))
A7: 59 | B7: Computing | C7: An Explainable Lightweight CBAM-CNN with Focal Loss for Brain Tumor MRI Classification | D7: Saiful Islam (American International University-Bangladesh); Safin Rahatil Tanim (American International University-Bangladesh); Kazi Tanvir (Universiti Kebangsaan Malaysia(UKM)); Kamruddin Nur (American International University-Bangladesh)* | E7: 22-47027-1@student.aiub.edu; 22-48551-3@student.aiub.edu; p170862@siswa.ukm.edu.my; kamruddin@aiub.edu | F7: kamruddin@aiub.edu | G7: T4P1 | H7: =IF(TRIM(G7)="","No","Yes") -> Yes | I7: =IF(TRIM(G7)="","",COUNTIFS($G$2:G7,G7)) -> 3 | J7: =IF(OR($A7="",TRIM($G7)=""),"",IFERROR(IF(INDEX(INDIRECT("'"&$G7&"'!F1:F100"),MATCH($A7,INDIRECT("'"&$G7&"'!A1:A100"),0))="","",INDEX(INDIRECT("'"&$G7&"'!F1:F100"),MATCH($A7,INDIRECT("'"&$G7&"'!A1:A100"),0))),"")) | L7: =IF(COUNT(J7:K7)<2,"",J7+K7) | M7: =IF(L7="","",RANK(L7,$L$2:$L$201,0))
A8: 61 | B8: Computing | C8: Beyond Fragmentation: A Causal Analysis of Unicode NFKC Normalization Effects in Dialectal Bengali NER | D8: Touhidur Rahman (American International University-Bangladesh); Alif Bin Islam (American International University-Bangladesh); Kazi Tanvir (Universiti Kebangsaan Malaysia(UKM)); Kamruddin Nur (American International University-Bangladesh)* | E8: 22-49381-3@student.aiub.edu; 22-49382-3@student.aiub.edu; p170862@siswa.ukm.edu.my; kamruddin@aiub.edu | F8: kamruddin@aiub.edu | G8: T2P1 | H8: =IF(TRIM(G8)="","No","Yes") -> Yes | I8: =IF(TRIM(G8)="","",COUNTIFS($G$2:G8,G8)) -> 1 | J8: =IF(OR($A8="",TRIM($G8)=""),"",IFERROR(IF(INDEX(INDIRECT("'"&$G8&"'!F1:F100"),MATCH($A8,INDIRECT("'"&$G8&"'!A1:A100"),0))="","",INDEX(INDIRECT("'"&$G8&"'!F1:F100"),MATCH($A8,INDIRECT("'"&$G8&"'!A1:A100"),0))),"")) -> 30 | L8: =IF(COUNT(J8:K8)<2,"",J8+K8) | M8: =IF(L8="","",RANK(L8,$L$2:$L$201,0))
A9: 64 | B9: Computing | C9: An Explainable Ensemble Learning Approach for Anemia Prediction Using Clinical and Biochemical Data | D9: Gulfame Jannat (American International University Bangladesh); MD. Toky Tajwer Mahin (American International University Bangladesh); MD. Sohanur Rahman Shohan ( American International University Bangladesh); Muhtasin Ifti (American International University Bangladesh); Aminun Nahar (American International University Bangladesh)*; Kamruddin Nur (American International University Bangladesh) | E9: 23-50293-1@student.aiub.edu; 22-48934-3@student.aiub.edu; 20-43672-2@student.aiub.edu; 23-50249-1@student.aiub.edu; aminun.nahar@aiub.edu; kamruddin@aiub.edu | F9: aminun.nahar@aiub.edu | G9: T4P4 | H9: =IF(TRIM(G9)="","No","Yes") -> Yes | I9: =IF(TRIM(G9)="","",COUNTIFS($G$2:G9,G9)) -> 2 | J9: =IF(OR($A9="",TRIM($G9)=""),"",IFERROR(IF(INDEX(INDIRECT("'"&$G9&"'!F1:F100"),MATCH($A9,INDIRECT("'"&$G9&"'!A1:A100"),0))="","",INDEX(INDIRECT("'"&$G9&"'!F1:F100"),MATCH($A9,INDIRECT("'"&$G9&"'!A1:A100"),0))),"")) | L9: =IF(COUNT(J9:K9)<2,"",J9+K9) | M9: =IF(L9="","",RANK(L9,$L$2:$L$201,0))
A10: 66 | B10: Computing | C10: Interpretable Psoriatic Lesion Classification via Multi-Cohort Gene Expression Profiling | D10: Shah Salehin Siddique Raduan (American International University-Bangladesh); Rayena Rahman (American International University-Bangladesh); Kamrun Nahar Sumaiya (American International University-Bangladesh); Kazi Tanvir (Universiti Kebangsaan Malaysia(UKM)); Kamruddin Nur (American International University-Bangladesh)* | E10: 23-52038-2@student.aiub.edu; 23-52055-2@student.aiub.edu; 23-52047-2@student.aiub.edu; p170862@siswa.ukm.edu.my; kamruddin@aiub.edu | F10: kamruddin@aiub.edu | G10: T2P1 | H10: =IF(TRIM(G10)="","No","Yes") -> Yes | I10: =IF(TRIM(G10)="","",COUNTIFS($G$2:G10,G10)) -> 2 | J10: =IF(OR($A10="",TRIM($G10)=""),"",IFERROR(IF(INDEX(INDIRECT("'"&$G10&"'!F1:F100"),MATCH($A10,INDIRECT("'"&$G10&"'!A1:A100"),0))="","",INDEX(INDIRECT("'"&$G10&"'!F1:F100"),MATCH($A10,INDIRECT("'"&$G10&"'!A1:A100"),0))),"")) | L10: =IF(COUNT(J10:K10)<2,"",J10+K10) | M10: =IF(L10="","",RANK(L10,$L$2:$L$201,0))
A11: 79 | B11: Computing | C11: Dual-Input ConvNeXt with Spatial Cross-Attention for Colonoscopy Mayo Scoring | D11: Md. Mamun Hossain ( Khwaja Yunus Ali University); Md.Abu Raihan ( Khwaja Yunus Ali University); Jarziz Ahmed ( Khwaja Yunus Ali University); F M Javed Mehedi Shamrat (Khwaja Yunus Ali University)*; Md. Asraf Ali (Khwaja Yunus Ali University) | E11: muhammed.mamun.131@gmail.com; raihan.cse@kyau.edu.bd; jarzizcse13th.kyau@gmail.com; shamrat.cse@kyau.edu.bd; asrafali@kyau.edu.bd | F11: shamrat.cse@kyau.edu.bd | G11: T4P6 | H11: =IF(TRIM(G11)="","No","Yes") -> Yes | I11: =IF(TRIM(G11)="","",COUNTIFS($G$2:G11,G11)) -> 1 | J11: =IF(OR($A11="",TRIM($G11)=""),"",IFERROR(IF(INDEX(INDIRECT("'"&$G11&"'!F1:F100"),MATCH($A11,INDIRECT("'"&$G11&"'!A1:A100"),0))="","",INDEX(INDIRECT("'"&$G11&"'!F1:F100"),MATCH($A11,INDIRECT("'"&$G11&"'!A1:A100"),0))),"")) | L11: =IF(COUNT(J11:K11)<2,"",J11+K11) | M11: =IF(L11="","",RANK(L11,$L$2:$L$201,0))
A12: 86 | B12: Computing | C12: DCAF-Net: Dual-Branch Convolutional Network with Spatial Cross-Attention Fusion for Thyroid Nodule Classification | D12: Syed Muntasin Fayaz (Khwaja Yunus Ali University); F M Javed Mehedi Shamrat (Khwaja Yunus Ali University)*; Md.Abu Raihan ( Khwaja Yunus Ali University); MD. Asraf Ali (Khwaja Yunus Ali University) | E12: muntasinfayaz@gmail.com; shamrat.cse@kyau.edu.bd; raihan.cse@kyau.edu.bd; asrafali@kyau.edu.bd | F12: shamrat.cse@kyau.edu.bd | G12: T4P4 | H12: =IF(TRIM(G12)="","No","Yes") -> Yes | I12: =IF(TRIM(G12)="","",COUNTIFS($G$2:G12,G12)) -> 3 | J12: =IF(OR($A12="",TRIM($G12)=""),"",IFERROR(IF(INDEX(INDIRECT("'"&$G12&"'!F1:F100"),MATCH($A12,INDIRECT("'"&$G12&"'!A1:A100"),0))="","",INDEX(INDIRECT("'"&$G12&"'!F1:F100"),MATCH($A12,INDIRECT("'"&$G12&"'!A1:A100"),0))),"")) | L12: =IF(COUNT(J12:K12)<2,"",J12+K12) | M12: =IF(L12="","",RANK(L12,$L$2:$L$201,0))
A13: 94 | B13: Computing | C13: TaxNet-Bangladesh: Building a Domain-Specific Tax Question-Answering System for Businesses in Bangladesh | D13: Raihan Kibria (University of Liberal Arts Bangladesh)*; Noshin Tabassum (University of Liberal Arts Bangladesh); Md. Nadimul Islam (University of Liberal Arts Bangladesh); Jannatul Ferdous Badhon (University of Liberal Arts Bangladesh); Monira Akter (University of Liberal Arts Bangladesh); MD KAVIUL HOSSAIN (University of Liberal Arts Bangladesh) | E13: raihan.kibria@ulab.edu.bd; noshin.tabassum.cse@ulab.edu.bd; nadimul.islam.cse@ulab.edu.bd; jannatul.ferdous3.cse@ulab.edu.bd; monira.akter.cse@ulab.edu.bd; kaviul.hossain@ulab.edu.bd | F13: raihan.kibria@ulab.edu.bd | G13: T1P2 | H13: =IF(TRIM(G13)="","No","Yes") -> Yes | I13: =IF(TRIM(G13)="","",COUNTIFS($G$2:G13,G13)) -> 1 | J13: =IF(OR($A13="",TRIM($G13)=""),"",IFERROR(IF(INDEX(INDIRECT("'"&$G13&"'!F1:F100"),MATCH($A13,INDIRECT("'"&$G13&"'!A1:A100"),0))="","",INDEX(INDIRECT("'"&$G13&"'!F1:F100"),MATCH($A13,INDIRECT("'"&$G13&"'!A1:A100"),0))),"")) | L13: =IF(COUNT(J13:K13)<2,"",J13+K13) | M13: =IF(L13="","",RANK(L13,$L$2:$L$201,0))
A14: 95 | B14: Computing | C14: MpoxFusionNet: Privacy-Aware Hybrid CNN-Transformer Fusion for Monkeypox Detection from Skin Lesion Images | D14: Anika Sarker Emo ( Khwaja Yunus Ali University); Shimanto Kumar ( Khwaja Yunus Ali University); F M Javed Mehedi Shamrat (Khwaja Yunus Ali University)*; Rashiduzzaman Shakil (Daffodil International University); Bonna Akter (University of Texas Rio Grande Valley); Md. Asraf Ali (Khwaja Yunus Ali University) | E14: anikaimo387@gmail.com; kshimanto70@gmail.com; shamrat.cse@kyau.edu.bd; rashiduzzaman.diucse@gmail.com; bonna.akter01@utrgv.edu; asrafali@kyau.edu.bd | F14: shamrat.cse@kyau.edu.bd | G14: T2P4 | H14: =IF(TRIM(G14)="","No","Yes") -> Yes | I14: =IF(TRIM(G14)="","",COUNTIFS($G$2:G14,G14)) -> 1 | J14: =IF(OR($A14="",TRIM($G14)=""),"",IFERROR(IF(INDEX(INDIRECT("'"&$G14&"'!F1:F100"),MATCH($A14,INDIRECT("'"&$G14&"'!A1:A100"),0))="","",INDEX(INDIRECT("'"&$G14&"'!F1:F100"),MATCH($A14,INDIRECT("'"&$G14&"'!A1:A100"),0))),"")) | L14: =IF(COUNT(J14:K14)<2,"",J14+K14) | M14: =IF(L14="","",RANK(L14,$L$2:$L$201,0))
A15: 100 | B15: Computing | C15: Multi-Task Swin Transformer for Automated Pneumonia Detection and Subtype Classification from Pediatric Chest X-Ray Images | D15: Md.Mahbubur Rahman (Patuakhali Science & Technology University); Pritha Kar (Patuakhali Science & Technology University )*; Romaiya Rechi ( Patuakhali Science & Technology University); Kaberi Chaki (Patuakhali Science & Technology University); Chinmay Bepery (Patuakhali Science & Technology University); Md. Atikqur Rahaman (Patuakhali Science & Technology University); Sarna Majumder (Patuakhali Science & Technology University) | E15: mahbub.cse@pstu.ac.bd; pritha18@cse.pstu.ac.bd; rechi18@cse.pstu.ac.bd; kaberi18@cse.pstu.ac.bd; chinmay.cse@pstu.ac.bd; atik.csit@pstu.ac.bd; saran.majumder90@gmail.com | F15: pritha18@cse.pstu.ac.bd | H15: =IF(TRIM(G15)="","No","Yes") -> No | I15: =IF(TRIM(G15)="","",COUNTIFS($G$2:G15,G15)) | J15: =IF(OR($A15="",TRIM($G15)=""),"",IFERROR(IF(INDEX(INDIRECT("'"&$G15&"'!F1:F100"),MATCH($A15,INDIRECT("'"&$G15&"'!A1:A100"),0))="","",INDEX(INDIRECT("'"&$G15&"'!F1:F100"),MATCH($A15,INDIRECT("'"&$G15&"'!A1:A100"),0))),"")) | L15: =IF(COUNT(J15:K15)<2,"",J15+K15) | M15: =IF(L15="","",RANK(L15,$L$2:$L$201,0))
A16: 104 | B16: Computing | C16: Quantum Machine Learning for Voice Pathology Detection: A Comparative Study with Classical Machine Learning and 1D-CNN Models | D16: Uttam Mahapatra (Uttara University)*; Md. Mehedi Hasan Tusar (Uttara University); Md Maniruz Zaman (Uttara University); Jiad Bin Asad (Uttara University); Md. Shamsul Islam (Uttara University); Amit Das (Uttara University) | E16: uttammahapatra211@gmail.com; its.mehedi.eee@gmail.com; mmzaman.ruet@gmail.com; jiadbinasad@gmail.com; islamshamsul127@gmail.com; amit.das.ruet@gmail.com | F16: uttammahapatra211@gmail.com | H16: =IF(TRIM(G16)="","No","Yes") -> No | I16: =IF(TRIM(G16)="","",COUNTIFS($G$2:G16,G16)) | J16: =IF(OR($A16="",TRIM($G16)=""),"",IFERROR(IF(INDEX(INDIRECT("'"&$G16&"'!F1:F100"),MATCH($A16,INDIRECT("'"&$G16&"'!A1:A100"),0))="","",INDEX(INDIRECT("'"&$G16&"'!F1:F100"),MATCH($A16,INDIRECT("'"&$G16&"'!A1:A100"),0))),"")) | L16: =IF(COUNT(J16:K16)<2,"",J16+K16) | M16: =IF(L16="","",RANK(L16,$L$2:$L$201,0))
A17: 124 | B17: Computing | C17: HybridOsteoX: A Knee Osteoporosis Explainable AI Framework Using Hybrid CNN-ViT Fusion | D17: Zarin Tasnim Rahman Tarin (North South University); Nawar Nooren Orpa (North South University)*; Sifat Momen (North South University) | E17: zarin.tarin@northsouth.edu; nawar.orpa@northsouth.edu; sifat.momen@northsouth.edu | F17: nawar.orpa@northsouth.edu | G17: T2P2 | H17: =IF(TRIM(G17)="","No","Yes") -> Yes | I17: =IF(TRIM(G17)="","",COUNTIFS($G$2:G17,G17)) -> 1 | J17: =IF(OR($A17="",TRIM($G17)=""),"",IFERROR(IF(INDEX(INDIRECT("'"&$G17&"'!F1:F100"),MATCH($A17,INDIRECT("'"&$G17&"'!A1:A100"),0))="","",INDEX(INDIRECT("'"&$G17&"'!F1:F100"),MATCH($A17,INDIRECT("'"&$G17&"'!A1:A100"),0))),"")) | L17: =IF(COUNT(J17:K17)<2,"",J17+K17) | M17: =IF(L17="","",RANK(L17,$L$2:$L$201,0))
A18: 127 | B18: Computing | C18: BanglaRhet: Benchmarking Classical and Transformer Models for Rhetorical and Persuasion Detection in Bangla Political Speech | D18: Rohit Kumar Sen (North East University Bangladesh)*; Anik Chowdhury (North East University Bangladesh) | E18: rohit.k.sen.neub@gmail.com; anikchowdhuryraj.neub@gmail.com | F18: rohit.k.sen.neub@gmail.com | G18: T2P2 | H18: =IF(TRIM(G18)="","No","Yes") -> Yes | I18: =IF(TRIM(G18)="","",COUNTIFS($G$2:G18,G18)) -> 2 | J18: =IF(OR($A18="",TRIM($G18)=""),"",IFERROR(IF(INDEX(INDIRECT("'"&$G18&"'!F1:F100"),MATCH($A18,INDIRECT("'"&$G18&"'!A1:A100"),0))="","",INDEX(INDIRECT("'"&$G18&"'!F1:F100"),MATCH($A18,INDIRECT("'"&$G18&"'!A1:A100"),0))),"")) | L18: =IF(COUNT(J18:K18)<2,"",J18+K18) | M18: =IF(L18="","",RANK(L18,$L$2:$L$201,0))
A19: 135 | B19: Computing | C19: FairHireATS: An Intersectional Bias Detection and Mitigation Framework for Automated Resume Screening | D19: Fahmida Salma (Sylhet Engineering College)*; Fariha Zarin (Sylhet Engineering College); Zarin Chowdhury (Sylhet Engineering College); Md. Lysuzzaman (Sylhet Engineering College) | E19: fahmidasalma071@sec.ac.bd; farihazrn@sec.ac.bd; ztasnim263@sec.ac.bd; l.zaman.cse@sec.ac.bd | F19: fahmidasalma071@sec.ac.bd | G19: T4P6 | H19: =IF(TRIM(G19)="","No","Yes") -> Yes | I19: =IF(TRIM(G19)="","",COUNTIFS($G$2:G19,G19)) -> 2 | J19: =IF(OR($A19="",TRIM($G19)=""),"",IFERROR(IF(INDEX(INDIRECT("'"&$G19&"'!F1:F100"),MATCH($A19,INDIRECT("'"&$G19&"'!A1:A100"),0))="","",INDEX(INDIRECT("'"&$G19&"'!F1:F100"),MATCH($A19,INDIRECT("'"&$G19&"'!A1:A100"),0))),"")) | L19: =IF(COUNT(J19:K19)<2,"",J19+K19) | M19: =IF(L19="","",RANK(L19,$L$2:$L$201,0))
A20: 138 | B20: Computing | C20: HalluciNet: A Multi-Granularity Contrastive Framework for Factual Hallucination Detection in Large Language Models | D20: Md. Siam Ansary (Ahsanullah University of Science and Technology)*; SUMONA ISLAM ZERIN (Ahsanullah University of Science and Technology) | E20: siamansary.aust@gmail.com; sumona.vnc@gmail.com | F20: siamansary.aust@gmail.com | G20: T4P1 | H20: =IF(TRIM(G20)="","No","Yes") -> Yes | I20: =IF(TRIM(G20)="","",COUNTIFS($G$2:G20,G20)) -> 4 | J20: =IF(OR($A20="",TRIM($G20)=""),"",IFERROR(IF(INDEX(INDIRECT("'"&$G20&"'!F1:F100"),MATCH($A20,INDIRECT("'"&$G20&"'!A1:A100"),0))="","",INDEX(INDIRECT("'"&$G20&"'!F1:F100"),MATCH($A20,INDIRECT("'"&$G20&"'!A1:A100"),0))),"")) | L20: =IF(COUNT(J20:K20)<2,"",J20+K20) | M20: =IF(L20="","",RANK(L20,$L$2:$L$201,0))
A21: 147 | B21: Computing | C21: SplitSeg: Generalizable Skin Lesion Segmentation with ResNeSt-UNet | D21: Saalim Araf (North South University)*; Khurshed . (North South University); Shaheer Shamsi (North South University); Saiba Adnan (North South University); Sifat Momen (North South University) | E21: saalim.araf@northsouth.edu; khurshed@northsouth.edu; shaheer.shamsi@northsouth.edu; saiba.adnan@northsouth.edu; sifat.momen@northsouth.edu | F21: saalim.araf@northsouth.edu | G21: T2P2 | H21: =IF(TRIM(G21)="","No","Yes") -> Yes | I21: =IF(TRIM(G21)="","",COUNTIFS($G$2:G21,G21)) -> 3 | J21: =IF(OR($A21="",TRIM($G21)=""),"",IFERROR(IF(INDEX(INDIRECT("'"&$G21&"'!F1:F100"),MATCH($A21,INDIRECT("'"&$G21&"'!A1:A100"),0))="","",INDEX(INDIRECT("'"&$G21&"'!F1:F100"),MATCH($A21,INDIRECT("'"&$G21&"'!A1:A100"),0))),"")) | L21: =IF(COUNT(J21:K21)<2,"",J21+K21) | M21: =IF(L21="","",RANK(L21,$L$2:$L$201,0))
